2021-09-23 11:48:20,085 ERROR: Exception on /background_process_test [GET] [in d:\py\vd\lib\site-packages\flask\app.py:1454]
Traceback (most recent call last):
  File "d:\py\vd\lib\site-packages\flask\app.py", line 2070, in wsgi_app
    response = self.full_dispatch_request()
  File "d:\py\vd\lib\site-packages\flask\app.py", line 1515, in full_dispatch_request
    rv = self.handle_user_exception(e)
  File "d:\py\vd\lib\site-packages\flask\app.py", line 1513, in full_dispatch_request
    rv = self.dispatch_request()
  File "d:\py\vd\lib\site-packages\flask\app.py", line 1499, in dispatch_request
    return self.ensure_sync(self.view_functions[rule.endpoint])(**req.view_args)
  File "d:\py\vd\app\routes.py", line 213, in background_process_test
    fileway=fd.askopenfile()
  File "c:\users\kharitonov\appdata\local\programs\python\python38\lib\tkinter\filedialog.py", line 400, in askopenfile
    filename = Open(**options).show()
  File "c:\users\kharitonov\appdata\local\programs\python\python38\lib\tkinter\commondialog.py", line 40, in show
    w = Frame(self.master)
  File "c:\users\kharitonov\appdata\local\programs\python\python38\lib\tkinter\__init__.py", line 3124, in __init__
    Widget.__init__(self, master, 'frame', cnf, {}, extra)
  File "c:\users\kharitonov\appdata\local\programs\python\python38\lib\tkinter\__init__.py", line 2572, in __init__
    self.tk.call(
RuntimeError: main thread is not in main loop
2021-09-23 12:02:45,467 INFO: Microblog startup [in d:\py\vd\app\__init__.py:57]
2021-09-23 12:03:34,917 INFO: Microblog startup [in d:\py\vd\app\__init__.py:57]
2021-09-23 12:03:54,124 ERROR: Exception on /background_process_test [GET] [in d:\py\vd\lib\site-packages\flask\app.py:1454]
Traceback (most recent call last):
  File "d:\py\vd\lib\site-packages\flask\app.py", line 2070, in wsgi_app
    response = self.full_dispatch_request()
  File "d:\py\vd\lib\site-packages\flask\app.py", line 1515, in full_dispatch_request
    rv = self.handle_user_exception(e)
  File "d:\py\vd\lib\site-packages\flask\app.py", line 1513, in full_dispatch_request
    rv = self.dispatch_request()
  File "d:\py\vd\lib\site-packages\flask\app.py", line 1499, in dispatch_request
    return self.ensure_sync(self.view_functions[rule.endpoint])(**req.view_args)
  File "d:\py\vd\app\routes.py", line 213, in background_process_test
    fileway=fd.askopenfile()
  File "c:\users\kharitonov\appdata\local\programs\python\python38\lib\tkinter\filedialog.py", line 400, in askopenfile
    filename = Open(**options).show()
  File "c:\users\kharitonov\appdata\local\programs\python\python38\lib\tkinter\commondialog.py", line 40, in show
    w = Frame(self.master)
  File "c:\users\kharitonov\appdata\local\programs\python\python38\lib\tkinter\__init__.py", line 3124, in __init__
    Widget.__init__(self, master, 'frame', cnf, {}, extra)
  File "c:\users\kharitonov\appdata\local\programs\python\python38\lib\tkinter\__init__.py", line 2572, in __init__
    self.tk.call(
RuntimeError: main thread is not in main loop
2021-09-23 12:04:28,149 INFO: Microblog startup [in d:\py\vd\app\__init__.py:57]
2021-09-23 12:04:52,934 ERROR: Exception on /background_process_test [GET] [in d:\py\vd\lib\site-packages\flask\app.py:1454]
Traceback (most recent call last):
  File "d:\py\vd\lib\site-packages\flask\app.py", line 2070, in wsgi_app
    response = self.full_dispatch_request()
  File "d:\py\vd\lib\site-packages\flask\app.py", line 1515, in full_dispatch_request
    rv = self.handle_user_exception(e)
  File "d:\py\vd\lib\site-packages\flask\app.py", line 1513, in full_dispatch_request
    rv = self.dispatch_request()
  File "d:\py\vd\lib\site-packages\flask\app.py", line 1499, in dispatch_request
    return self.ensure_sync(self.view_functions[rule.endpoint])(**req.view_args)
  File "d:\py\vd\app\routes.py", line 213, in background_process_test
    fileway=fd.askopenfile()
  File "c:\users\kharitonov\appdata\local\programs\python\python38\lib\tkinter\filedialog.py", line 400, in askopenfile
    filename = Open(**options).show()
  File "c:\users\kharitonov\appdata\local\programs\python\python38\lib\tkinter\commondialog.py", line 40, in show
    w = Frame(self.master)
  File "c:\users\kharitonov\appdata\local\programs\python\python38\lib\tkinter\__init__.py", line 3124, in __init__
    Widget.__init__(self, master, 'frame', cnf, {}, extra)
  File "c:\users\kharitonov\appdata\local\programs\python\python38\lib\tkinter\__init__.py", line 2572, in __init__
    self.tk.call(
RuntimeError: main thread is not in main loop
2021-09-23 17:41:34,026 INFO: Microblog startup [in d:\py\vd\app\__init__.py:57]
2021-09-23 17:45:03,484 INFO: Microblog startup [in d:\py\vd\app\__init__.py:57]
2021-09-24 14:33:34,366 INFO: Microblog startup [in d:\py\vd\app\__init__.py:57]
2021-09-24 14:34:36,038 ERROR: Exception on /background_process_test [GET] [in d:\py\vd\lib\site-packages\flask\app.py:1454]
Traceback (most recent call last):
  File "d:\py\vd\lib\site-packages\flask\app.py", line 2070, in wsgi_app
    response = self.full_dispatch_request()
  File "d:\py\vd\lib\site-packages\flask\app.py", line 1515, in full_dispatch_request
    rv = self.handle_user_exception(e)
  File "d:\py\vd\lib\site-packages\flask\app.py", line 1513, in full_dispatch_request
    rv = self.dispatch_request()
  File "d:\py\vd\lib\site-packages\flask\app.py", line 1499, in dispatch_request
    return self.ensure_sync(self.view_functions[rule.endpoint])(**req.view_args)
  File "d:\py\vd\app\routes.py", line 213, in background_process_test
    fileway=fd.askopenfile()
  File "c:\users\kharitonov\appdata\local\programs\python\python38\lib\tkinter\filedialog.py", line 400, in askopenfile
    filename = Open(**options).show()
  File "c:\users\kharitonov\appdata\local\programs\python\python38\lib\tkinter\commondialog.py", line 40, in show
    w = Frame(self.master)
  File "c:\users\kharitonov\appdata\local\programs\python\python38\lib\tkinter\__init__.py", line 3124, in __init__
    Widget.__init__(self, master, 'frame', cnf, {}, extra)
  File "c:\users\kharitonov\appdata\local\programs\python\python38\lib\tkinter\__init__.py", line 2572, in __init__
    self.tk.call(
RuntimeError: main thread is not in main loop
2021-09-24 14:34:38,395 ERROR: Exception on /background_process_test [GET] [in d:\py\vd\lib\site-packages\flask\app.py:1454]
Traceback (most recent call last):
  File "d:\py\vd\lib\site-packages\flask\app.py", line 2070, in wsgi_app
    response = self.full_dispatch_request()
  File "d:\py\vd\lib\site-packages\flask\app.py", line 1515, in full_dispatch_request
    rv = self.handle_user_exception(e)
  File "d:\py\vd\lib\site-packages\flask\app.py", line 1513, in full_dispatch_request
    rv = self.dispatch_request()
  File "d:\py\vd\lib\site-packages\flask\app.py", line 1499, in dispatch_request
    return self.ensure_sync(self.view_functions[rule.endpoint])(**req.view_args)
  File "d:\py\vd\app\routes.py", line 213, in background_process_test
    fileway=fd.askopenfile()
  File "c:\users\kharitonov\appdata\local\programs\python\python38\lib\tkinter\filedialog.py", line 400, in askopenfile
    filename = Open(**options).show()
  File "c:\users\kharitonov\appdata\local\programs\python\python38\lib\tkinter\commondialog.py", line 40, in show
    w = Frame(self.master)
  File "c:\users\kharitonov\appdata\local\programs\python\python38\lib\tkinter\__init__.py", line 3124, in __init__
    Widget.__init__(self, master, 'frame', cnf, {}, extra)
  File "c:\users\kharitonov\appdata\local\programs\python\python38\lib\tkinter\__init__.py", line 2572, in __init__
    self.tk.call(
RuntimeError: main thread is not in main loop
2021-09-24 14:45:27,134 INFO: Microblog startup [in d:\py\vd\app\__init__.py:57]
2021-09-24 14:45:48,003 ERROR: Exception on /background_process_test [GET] [in d:\py\vd\lib\site-packages\flask\app.py:1454]
Traceback (most recent call last):
  File "d:\py\vd\lib\site-packages\flask\app.py", line 2070, in wsgi_app
    response = self.full_dispatch_request()
  File "d:\py\vd\lib\site-packages\flask\app.py", line 1515, in full_dispatch_request
    rv = self.handle_user_exception(e)
  File "d:\py\vd\lib\site-packages\flask\app.py", line 1513, in full_dispatch_request
    rv = self.dispatch_request()
  File "d:\py\vd\lib\site-packages\flask\app.py", line 1499, in dispatch_request
    return self.ensure_sync(self.view_functions[rule.endpoint])(**req.view_args)
  File "d:\py\vd\app\routes.py", line 213, in background_process_test
    fileway=fd.askopenfile()
  File "c:\users\kharitonov\appdata\local\programs\python\python38\lib\tkinter\filedialog.py", line 402, in askopenfile
    return open(filename, mode)
PermissionError: [Errno 13] Permission denied: 'D:/Backup_Win7_full_b1_s1_v1.tib'
2021-09-24 14:52:20,070 INFO: Microblog startup [in d:\py\vd\app\__init__.py:57]
2021-09-24 14:52:30,836 ERROR: Exception on /background_process_test [GET] [in d:\py\vd\lib\site-packages\flask\app.py:1454]
Traceback (most recent call last):
  File "d:\py\vd\lib\site-packages\flask\app.py", line 2070, in wsgi_app
    response = self.full_dispatch_request()
  File "d:\py\vd\lib\site-packages\flask\app.py", line 1515, in full_dispatch_request
    rv = self.handle_user_exception(e)
  File "d:\py\vd\lib\site-packages\flask\app.py", line 1513, in full_dispatch_request
    rv = self.dispatch_request()
  File "d:\py\vd\lib\site-packages\flask\app.py", line 1499, in dispatch_request
    return self.ensure_sync(self.view_functions[rule.endpoint])(**req.view_args)
  File "d:\py\vd\app\routes.py", line 215, in background_process_test
    data = ddata
NameError: name 'ddata' is not defined
2021-09-24 15:49:23,639 INFO: Microblog startup [in d:\py\vd\app\__init__.py:57]
2021-09-24 15:51:09,317 INFO: Microblog startup [in d:\py\vd\app\__init__.py:57]
2021-09-28 14:33:48,553 INFO: Microblog startup [in d:\py\vd\app\__init__.py:57]
2021-09-28 14:34:50,695 INFO: Microblog startup [in d:\py\vd\app\__init__.py:57]
2021-09-28 17:13:04,948 INFO: Microblog startup [in d:\py\vd\app\__init__.py:57]
