2021-09-28 17:52:01,270 INFO: Microblog startup [in d:\py\vd\app\__init__.py:57]
2021-09-28 17:56:05,105 INFO: Microblog startup [in d:\py\vd\app\__init__.py:57]
2021-09-28 17:56:56,925 ERROR: Exception on /upload [GET] [in d:\py\vd\lib\site-packages\flask\app.py:1454]
Traceback (most recent call last):
  File "d:\py\vd\lib\site-packages\flask\app.py", line 2070, in wsgi_app
    response = self.full_dispatch_request()
  File "d:\py\vd\lib\site-packages\flask\app.py", line 1515, in full_dispatch_request
    rv = self.handle_user_exception(e)
  File "d:\py\vd\lib\site-packages\flask\app.py", line 1513, in full_dispatch_request
    rv = self.dispatch_request()
  File "d:\py\vd\lib\site-packages\flask\app.py", line 1499, in dispatch_request
    return self.ensure_sync(self.view_functions[rule.endpoint])(**req.view_args)
  File "d:\py\vd\app\routes.py", line 236, in uploaddd
    files = os.listdir(app.config['UPLOAD_PATH'])
FileNotFoundError: [WinError 3] Системе не удается найти указанный путь: 'uploads'
2021-09-28 18:00:26,013 ERROR: Exception on /upload [GET] [in d:\py\vd\lib\site-packages\flask\app.py:1454]
Traceback (most recent call last):
  File "d:\py\vd\lib\site-packages\flask\app.py", line 2070, in wsgi_app
    response = self.full_dispatch_request()
  File "d:\py\vd\lib\site-packages\flask\app.py", line 1515, in full_dispatch_request
    rv = self.handle_user_exception(e)
  File "d:\py\vd\lib\site-packages\flask\app.py", line 1513, in full_dispatch_request
    rv = self.dispatch_request()
  File "d:\py\vd\lib\site-packages\flask\app.py", line 1499, in dispatch_request
    return self.ensure_sync(self.view_functions[rule.endpoint])(**req.view_args)
  File "d:\py\vd\app\routes.py", line 236, in uploaddd
    files = os.listdir(app.config['UPLOAD_PATH'])
FileNotFoundError: [WinError 3] Системе не удается найти указанный путь: 'uploads'
2021-09-28 18:00:40,958 ERROR: Exception on /upload [GET] [in d:\py\vd\lib\site-packages\flask\app.py:1454]
Traceback (most recent call last):
  File "d:\py\vd\lib\site-packages\flask\app.py", line 2070, in wsgi_app
    response = self.full_dispatch_request()
  File "d:\py\vd\lib\site-packages\flask\app.py", line 1515, in full_dispatch_request
    rv = self.handle_user_exception(e)
  File "d:\py\vd\lib\site-packages\flask\app.py", line 1513, in full_dispatch_request
    rv = self.dispatch_request()
  File "d:\py\vd\lib\site-packages\flask\app.py", line 1499, in dispatch_request
    return self.ensure_sync(self.view_functions[rule.endpoint])(**req.view_args)
  File "d:\py\vd\app\routes.py", line 236, in uploaddd
    files = os.listdir(app.config['UPLOAD_PATH'])
FileNotFoundError: [WinError 3] Системе не удается найти указанный путь: 'uploads'
2021-10-14 09:25:14,390 INFO: Microblog startup [in d:\py\vd\app\__init__.py:57]
2021-10-14 09:25:25,029 ERROR: Exception on /upload [GET] [in d:\py\vd\lib\site-packages\flask\app.py:1454]
Traceback (most recent call last):
  File "d:\py\vd\lib\site-packages\flask\app.py", line 2070, in wsgi_app
    response = self.full_dispatch_request()
  File "d:\py\vd\lib\site-packages\flask\app.py", line 1515, in full_dispatch_request
    rv = self.handle_user_exception(e)
  File "d:\py\vd\lib\site-packages\flask\app.py", line 1513, in full_dispatch_request
    rv = self.dispatch_request()
  File "d:\py\vd\lib\site-packages\flask\app.py", line 1499, in dispatch_request
    return self.ensure_sync(self.view_functions[rule.endpoint])(**req.view_args)
  File "d:\py\vd\app\routes.py", line 236, in uploaddd
    files = os.listdir(app.config['UPLOAD_PATH'])
FileNotFoundError: [WinError 3] Системе не удается найти указанный путь: 'static'
